WARNING:uvicorn.error:Invalid HTTP request received.
Traceback (most recent call last):
  File "/usr/local/lib/python3.8/dist-packages/uvicorn/protocols/http/h11_impl.py", line 172, in handle_events
    event = self.conn.next_event()
  File "/usr/local/lib/python3.8/dist-packages/h11/_connection.py", line 443, in next_event
    exc._reraise_as_remote_protocol_error()
  File "/usr/local/lib/python3.8/dist-packages/h11/_util.py", line 76, in _reraise_as_remote_protocol_error
    raise self
  File "/usr/local/lib/python3.8/dist-packages/h11/_connection.py", line 425, in next_event
    event = self._extract_next_receive_event()
  File "/usr/local/lib/python3.8/dist-packages/h11/_connection.py", line 367, in _extract_next_receive_event
    event = self._reader(self._receive_buffer)
  File "/usr/local/lib/python3.8/dist-packages/h11/_readers.py", line 68, in maybe_read_from_IDLE_client
    raise LocalProtocolError("illegal request line")
h11._util.RemoteProtocolError: illegal request line
WARNING:uvicorn.error:Invalid HTTP request received.
Traceback (most recent call last):
  File "/usr/local/lib/python3.8/dist-packages/uvicorn/protocols/http/h11_impl.py", line 172, in handle_events
    event = self.conn.next_event()
  File "/usr/local/lib/python3.8/dist-packages/h11/_connection.py", line 443, in next_event
    exc._reraise_as_remote_protocol_error()
  File "/usr/local/lib/python3.8/dist-packages/h11/_util.py", line 76, in _reraise_as_remote_protocol_error
    raise self
  File "/usr/local/lib/python3.8/dist-packages/h11/_connection.py", line 425, in next_event
    event = self._extract_next_receive_event()
  File "/usr/local/lib/python3.8/dist-packages/h11/_connection.py", line 367, in _extract_next_receive_event
    event = self._reader(self._receive_buffer)
  File "/usr/local/lib/python3.8/dist-packages/h11/_readers.py", line 68, in maybe_read_from_IDLE_client
    raise LocalProtocolError("illegal request line")
h11._util.RemoteProtocolError: illegal request line
WARNING:uvicorn.error:Invalid HTTP request received.
Traceback (most recent call last):
  File "/usr/local/lib/python3.8/dist-packages/uvicorn/protocols/http/h11_impl.py", line 172, in handle_events
    event = self.conn.next_event()
  File "/usr/local/lib/python3.8/dist-packages/h11/_connection.py", line 443, in next_event
    exc._reraise_as_remote_protocol_error()
  File "/usr/local/lib/python3.8/dist-packages/h11/_util.py", line 76, in _reraise_as_remote_protocol_error
    raise self
  File "/usr/local/lib/python3.8/dist-packages/h11/_connection.py", line 425, in next_event
    event = self._extract_next_receive_event()
  File "/usr/local/lib/python3.8/dist-packages/h11/_connection.py", line 367, in _extract_next_receive_event
    event = self._reader(self._receive_buffer)
  File "/usr/local/lib/python3.8/dist-packages/h11/_readers.py", line 72, in maybe_read_from_IDLE_client
    matches = validate(
  File "/usr/local/lib/python3.8/dist-packages/h11/_util.py", line 88, in validate
    raise LocalProtocolError(msg)
h11._util.RemoteProtocolError: illegal request line: bytearray(b'\x16\x03\x01\x02\x00\x01\x00\x01\xfc\x03\x03\xc2\x92\xb6\x8b\x88\xb9\xae\x19\xc0\xfdcq2\xa8\x13Z\x12\xc8\xd4;\x9b\xdfy\xbcqX\xd925\xd7\rg 0k\xaa!\xa9\x95\xc23\xa6p\xb8\x9b\x1dX\xe9,\xe2\xe6\xf4\x00\xdf\x1a\xc8\xcd\x85{\xeb,>\x05%\xa8\x00 ')
WARNING:uvicorn.error:Invalid HTTP request received.
Traceback (most recent call last):
  File "/usr/local/lib/python3.8/dist-packages/uvicorn/protocols/http/h11_impl.py", line 172, in handle_events
    event = self.conn.next_event()
  File "/usr/local/lib/python3.8/dist-packages/h11/_connection.py", line 443, in next_event
    exc._reraise_as_remote_protocol_error()
  File "/usr/local/lib/python3.8/dist-packages/h11/_util.py", line 76, in _reraise_as_remote_protocol_error
    raise self
  File "/usr/local/lib/python3.8/dist-packages/h11/_connection.py", line 425, in next_event
    event = self._extract_next_receive_event()
  File "/usr/local/lib/python3.8/dist-packages/h11/_connection.py", line 367, in _extract_next_receive_event
    event = self._reader(self._receive_buffer)
  File "/usr/local/lib/python3.8/dist-packages/h11/_readers.py", line 68, in maybe_read_from_IDLE_client
    raise LocalProtocolError("illegal request line")
h11._util.RemoteProtocolError: illegal request line
WARNING:uvicorn.error:Invalid HTTP request received.
Traceback (most recent call last):
  File "/usr/local/lib/python3.8/dist-packages/uvicorn/protocols/http/h11_impl.py", line 172, in handle_events
    event = self.conn.next_event()
  File "/usr/local/lib/python3.8/dist-packages/h11/_connection.py", line 443, in next_event
    exc._reraise_as_remote_protocol_error()
  File "/usr/local/lib/python3.8/dist-packages/h11/_util.py", line 76, in _reraise_as_remote_protocol_error
    raise self
  File "/usr/local/lib/python3.8/dist-packages/h11/_connection.py", line 425, in next_event
    event = self._extract_next_receive_event()
  File "/usr/local/lib/python3.8/dist-packages/h11/_connection.py", line 367, in _extract_next_receive_event
    event = self._reader(self._receive_buffer)
  File "/usr/local/lib/python3.8/dist-packages/h11/_readers.py", line 72, in maybe_read_from_IDLE_client
    matches = validate(
  File "/usr/local/lib/python3.8/dist-packages/h11/_util.py", line 88, in validate
    raise LocalProtocolError(msg)
h11._util.RemoteProtocolError: illegal request line: bytearray(b"\x16\x03\x01\x02\x00\x01\x00\x01\xfc\x03\x03\xf8s\x9aE\x96\xec\x9e\xe5C\x05\x8a\xc5-X\x8eI\xdcQ\xb7\xf5\xe9\t\x90\xa6\x0cK\xa3\x87\x0c\xa1\x1d\xe3 \xcfyK\x8f\x0f\x1c\x16\xc5T\x86\x98\xfb\xfe^\xf3E\x84\x05\r\xfe\x91|\'\xd8\x10\xff\xf1\xbd\xc5\x95\xc9\xa0\x00 JJ\x13\x01\x13\x02\x13\x03\xc0+\xc0/\xc0,\xc00\xcc\xa9\xcc\xa8\xc0\x13\xc0\x14\x00\x9c\x00\x9d\x00/\x005\x01\x00\x01\x93**\x00\x00\x00\x17\x00\x00\xff\x01\x00\x01\x00\x00")
WARNING:uvicorn.error:Invalid HTTP request received.
Traceback (most recent call last):
  File "/usr/local/lib/python3.8/dist-packages/uvicorn/protocols/http/h11_impl.py", line 172, in handle_events
    event = self.conn.next_event()
  File "/usr/local/lib/python3.8/dist-packages/h11/_connection.py", line 443, in next_event
    exc._reraise_as_remote_protocol_error()
  File "/usr/local/lib/python3.8/dist-packages/h11/_util.py", line 76, in _reraise_as_remote_protocol_error
    raise self
  File "/usr/local/lib/python3.8/dist-packages/h11/_connection.py", line 425, in next_event
    event = self._extract_next_receive_event()
  File "/usr/local/lib/python3.8/dist-packages/h11/_connection.py", line 367, in _extract_next_receive_event
    event = self._reader(self._receive_buffer)
  File "/usr/local/lib/python3.8/dist-packages/h11/_readers.py", line 68, in maybe_read_from_IDLE_client
    raise LocalProtocolError("illegal request line")
h11._util.RemoteProtocolError: illegal request line
